2023-02-12 14:58:47,200 INFO    StreamThr :5084 [internal.py:wandb_internal():88] W&B internal server running at pid: 5084, started at: 2023-02-12 14:58:47.199906
2023-02-12 14:58:47,202 DEBUG   HandlerThread:5084 [handler.py:handle_request():139] handle_request: status
2023-02-12 14:58:47,206 DEBUG   SenderThread:5084 [sender.py:send_request():317] send_request: status
2023-02-12 14:58:47,207 DEBUG   SenderThread:5084 [sender.py:send():303] send: header
2023-02-12 14:58:47,208 INFO    WriterThread:5084 [datastore.py:open_for_write():75] open: D:\github\seven-sees-net\wandb\run-20230212_145847-380mlxi8\run-380mlxi8.wandb
2023-02-12 14:58:47,227 DEBUG   SenderThread:5084 [sender.py:send():303] send: run
2023-02-12 14:58:47,822 ERROR   SenderThread:5084 [internal_api.py:execute():213] 404 response executing GraphQL.
2023-02-12 14:58:47,822 ERROR   SenderThread:5084 [internal_api.py:execute():214] {"errors":[{"message":"project not found","path":["upsertBucket"]}],"data":{"upsertBucket":null}}
2023-02-12 14:58:48,231 INFO    WriterThread:5084 [datastore.py:close():279] close: D:\github\seven-sees-net\wandb\run-20230212_145847-380mlxi8\run-380mlxi8.wandb
2023-02-12 14:58:48,231 INFO    HandlerThread:5084 [handler.py:finish():814] shutting down handler
2023-02-12 14:58:48,231 ERROR   StreamThr :5084 [internal.py:wandb_internal():163] Thread SenderThread:
Traceback (most recent call last):
  File "G:\anaconda\envs\open-mmlab\lib\site-packages\wandb\sdk\lib\retry.py", line 113, in __call__
    result = self._call_fn(*args, **kwargs)
  File "G:\anaconda\envs\open-mmlab\lib\site-packages\wandb\sdk\internal\internal_api.py", line 210, in execute
    return self.client.execute(*args, **kwargs)  # type: ignore
  File "G:\anaconda\envs\open-mmlab\lib\site-packages\wandb\vendor\gql-0.2.0\wandb_gql\client.py", line 52, in execute
    result = self._get_result(document, *args, **kwargs)
  File "G:\anaconda\envs\open-mmlab\lib\site-packages\wandb\vendor\gql-0.2.0\wandb_gql\client.py", line 60, in _get_result
    return self.transport.execute(document, *args, **kwargs)
  File "G:\anaconda\envs\open-mmlab\lib\site-packages\wandb\vendor\gql-0.2.0\wandb_gql\transport\requests.py", line 39, in execute
    request.raise_for_status()
  File "G:\anaconda\envs\open-mmlab\lib\site-packages\requests\models.py", line 1021, in raise_for_status
    raise HTTPError(http_error_msg, response=self)
requests.exceptions.HTTPError: 404 Client Error: Not Found for url: https://api.wandb.ai/graphql

During handling of the above exception, another exception occurred:

Traceback (most recent call last):
  File "G:\anaconda\envs\open-mmlab\lib\site-packages\wandb\apis\normalize.py", line 26, in wrapper
    return func(*args, **kwargs)
  File "G:\anaconda\envs\open-mmlab\lib\site-packages\wandb\sdk\internal\internal_api.py", line 1516, in upsert_run
    response = self.gql(
  File "G:\anaconda\envs\open-mmlab\lib\site-packages\wandb\sdk\lib\retry.py", line 129, in __call__
    retry_timedelta_triggered = check_retry_fn(e)
  File "G:\anaconda\envs\open-mmlab\lib\site-packages\wandb\util.py", line 1049, in check_retry_fn
    return fallback_retry_fn(e)
  File "G:\anaconda\envs\open-mmlab\lib\site-packages\wandb\util.py", line 996, in no_retry_auth
    raise CommError("Permission denied, ask the project owner to grant you access")
wandb.errors.CommError: Permission denied, ask the project owner to grant you access

During handling of the above exception, another exception occurred:

Traceback (most recent call last):
  File "G:\anaconda\envs\open-mmlab\lib\site-packages\wandb\sdk\internal\internal_util.py", line 50, in run
    self._run()
  File "G:\anaconda\envs\open-mmlab\lib\site-packages\wandb\sdk\internal\internal_util.py", line 101, in _run
    self._process(record)
  File "G:\anaconda\envs\open-mmlab\lib\site-packages\wandb\sdk\internal\internal.py", line 308, in _process
    self._sm.send(record)
  File "G:\anaconda\envs\open-mmlab\lib\site-packages\wandb\sdk\internal\sender.py", line 305, in send
    send_handler(record)
  File "G:\anaconda\envs\open-mmlab\lib\site-packages\wandb\sdk\internal\sender.py", line 797, in send_run
    self._init_run(run, config_value_dict)
  File "G:\anaconda\envs\open-mmlab\lib\site-packages\wandb\sdk\internal\sender.py", line 823, in _init_run
    server_run, inserted, server_messages = self._api.upsert_run(
  File "G:\anaconda\envs\open-mmlab\lib\site-packages\wandb\apis\normalize.py", line 62, in wrapper
    raise CommError(message, err).with_traceback(sys.exc_info()[2])
  File "G:\anaconda\envs\open-mmlab\lib\site-packages\wandb\apis\normalize.py", line 26, in wrapper
    return func(*args, **kwargs)
  File "G:\anaconda\envs\open-mmlab\lib\site-packages\wandb\sdk\internal\internal_api.py", line 1516, in upsert_run
    response = self.gql(
  File "G:\anaconda\envs\open-mmlab\lib\site-packages\wandb\sdk\lib\retry.py", line 129, in __call__
    retry_timedelta_triggered = check_retry_fn(e)
  File "G:\anaconda\envs\open-mmlab\lib\site-packages\wandb\util.py", line 1049, in check_retry_fn
    return fallback_retry_fn(e)
  File "G:\anaconda\envs\open-mmlab\lib\site-packages\wandb\util.py", line 996, in no_retry_auth
    raise CommError("Permission denied, ask the project owner to grant you access")
wandb.errors.CommError: Permission denied, ask the project owner to grant you access
